2022-05-04 18:53:40 ERROR Traceback (most recent call last):
  File "/home/ubuntu/anaconda3/envs/grand/lib/python3.7/site-packages/wandb/apis/normalize.py", line 22, in wrapper
    return func(*args, **kwargs)
  File "/home/ubuntu/anaconda3/envs/grand/lib/python3.7/site-packages/wandb/sdk/internal/internal_api.py", line 581, in sweep
    raise ValueError(f"Sweep {entity}/{project}/{sweep} not found")
ValueError: Sweep graph_neural_diffusion/hetero_tune_2hops/olbfb6ll not found

During handling of the above exception, another exception occurred:

Traceback (most recent call last):
  File "/home/ubuntu/anaconda3/envs/grand/lib/python3.7/site-packages/wandb/cli/cli.py", line 95, in wrapper
    return func(*args, **kwargs)
  File "/home/ubuntu/anaconda3/envs/grand/lib/python3.7/site-packages/wandb/cli/cli.py", line 1205, in agent
    wandb_agent.agent(sweep_id, entity=entity, project=project, count=count)
  File "/home/ubuntu/anaconda3/envs/grand/lib/python3.7/site-packages/wandb/wandb_agent.py", line 612, in agent
    count=count,
  File "/home/ubuntu/anaconda3/envs/grand/lib/python3.7/site-packages/wandb/wandb_agent.py", line 548, in run_agent
    agent.run()
  File "/home/ubuntu/anaconda3/envs/grand/lib/python3.7/site-packages/wandb/wandb_agent.py", line 181, in run
    sweep_obj = self._api.sweep(self._sweep_id, "{}")
  File "/home/ubuntu/anaconda3/envs/grand/lib/python3.7/site-packages/wandb/apis/internal.py", line 99, in sweep
    return self.api.sweep(*args, **kwargs)
  File "/home/ubuntu/anaconda3/envs/grand/lib/python3.7/site-packages/wandb/apis/normalize.py", line 58, in wrapper
    raise CommError(message, err).with_traceback(sys.exc_info()[2])
  File "/home/ubuntu/anaconda3/envs/grand/lib/python3.7/site-packages/wandb/apis/normalize.py", line 22, in wrapper
    return func(*args, **kwargs)
  File "/home/ubuntu/anaconda3/envs/grand/lib/python3.7/site-packages/wandb/sdk/internal/internal_api.py", line 581, in sweep
    raise ValueError(f"Sweep {entity}/{project}/{sweep} not found")
wandb.errors.CommError: Sweep graph_neural_diffusion/hetero_tune_2hops/olbfb6ll not found

2022-05-04 18:53:40 ERROR Traceback (most recent call last):
  File "/home/ubuntu/anaconda3/envs/grand/lib/python3.7/site-packages/wandb/apis/normalize.py", line 22, in wrapper
    return func(*args, **kwargs)
  File "/home/ubuntu/anaconda3/envs/grand/lib/python3.7/site-packages/wandb/sdk/internal/internal_api.py", line 581, in sweep
    raise ValueError(f"Sweep {entity}/{project}/{sweep} not found")
ValueError: Sweep graph_neural_diffusion/hetero_tune_2hops/olbfb6ll not found

During handling of the above exception, another exception occurred:

Traceback (most recent call last):
  File "/home/ubuntu/anaconda3/envs/grand/lib/python3.7/site-packages/wandb/cli/cli.py", line 95, in wrapper
    return func(*args, **kwargs)
  File "/home/ubuntu/anaconda3/envs/grand/lib/python3.7/site-packages/wandb/cli/cli.py", line 1205, in agent
    wandb_agent.agent(sweep_id, entity=entity, project=project, count=count)
  File "/home/ubuntu/anaconda3/envs/grand/lib/python3.7/site-packages/wandb/wandb_agent.py", line 612, in agent
    count=count,
  File "/home/ubuntu/anaconda3/envs/grand/lib/python3.7/site-packages/wandb/wandb_agent.py", line 548, in run_agent
    agent.run()
  File "/home/ubuntu/anaconda3/envs/grand/lib/python3.7/site-packages/wandb/wandb_agent.py", line 181, in run
    sweep_obj = self._api.sweep(self._sweep_id, "{}")
  File "/home/ubuntu/anaconda3/envs/grand/lib/python3.7/site-packages/wandb/apis/internal.py", line 99, in sweep
    return self.api.sweep(*args, **kwargs)
  File "/home/ubuntu/anaconda3/envs/grand/lib/python3.7/site-packages/wandb/apis/normalize.py", line 58, in wrapper
    raise CommError(message, err).with_traceback(sys.exc_info()[2])
  File "/home/ubuntu/anaconda3/envs/grand/lib/python3.7/site-packages/wandb/apis/normalize.py", line 22, in wrapper
    return func(*args, **kwargs)
  File "/home/ubuntu/anaconda3/envs/grand/lib/python3.7/site-packages/wandb/sdk/internal/internal_api.py", line 581, in sweep
    raise ValueError(f"Sweep {entity}/{project}/{sweep} not found")
wandb.errors.CommError: Sweep graph_neural_diffusion/hetero_tune_2hops/olbfb6ll not found

2022-05-04 18:53:40 ERROR Traceback (most recent call last):
  File "/home/ubuntu/anaconda3/envs/grand/lib/python3.7/site-packages/wandb/apis/normalize.py", line 22, in wrapper
    return func(*args, **kwargs)
  File "/home/ubuntu/anaconda3/envs/grand/lib/python3.7/site-packages/wandb/sdk/internal/internal_api.py", line 581, in sweep
    raise ValueError(f"Sweep {entity}/{project}/{sweep} not found")
ValueError: Sweep graph_neural_diffusion/hetero_tune_2hops/olbfb6ll not found

During handling of the above exception, another exception occurred:

Traceback (most recent call last):
  File "/home/ubuntu/anaconda3/envs/grand/lib/python3.7/site-packages/wandb/cli/cli.py", line 95, in wrapper
    return func(*args, **kwargs)
  File "/home/ubuntu/anaconda3/envs/grand/lib/python3.7/site-packages/wandb/cli/cli.py", line 1205, in agent
    wandb_agent.agent(sweep_id, entity=entity, project=project, count=count)
  File "/home/ubuntu/anaconda3/envs/grand/lib/python3.7/site-packages/wandb/wandb_agent.py", line 612, in agent
    count=count,
  File "/home/ubuntu/anaconda3/envs/grand/lib/python3.7/site-packages/wandb/wandb_agent.py", line 548, in run_agent
    agent.run()
  File "/home/ubuntu/anaconda3/envs/grand/lib/python3.7/site-packages/wandb/wandb_agent.py", line 181, in run
    sweep_obj = self._api.sweep(self._sweep_id, "{}")
  File "/home/ubuntu/anaconda3/envs/grand/lib/python3.7/site-packages/wandb/apis/internal.py", line 99, in sweep
    return self.api.sweep(*args, **kwargs)
  File "/home/ubuntu/anaconda3/envs/grand/lib/python3.7/site-packages/wandb/apis/normalize.py", line 58, in wrapper
    raise CommError(message, err).with_traceback(sys.exc_info()[2])
  File "/home/ubuntu/anaconda3/envs/grand/lib/python3.7/site-packages/wandb/apis/normalize.py", line 22, in wrapper
    return func(*args, **kwargs)
  File "/home/ubuntu/anaconda3/envs/grand/lib/python3.7/site-packages/wandb/sdk/internal/internal_api.py", line 581, in sweep
    raise ValueError(f"Sweep {entity}/{project}/{sweep} not found")
wandb.errors.CommError: Sweep graph_neural_diffusion/hetero_tune_2hops/olbfb6ll not found

2022-05-04 18:53:40 ERROR Traceback (most recent call last):
  File "/home/ubuntu/anaconda3/envs/grand/lib/python3.7/site-packages/wandb/apis/normalize.py", line 22, in wrapper
    return func(*args, **kwargs)
  File "/home/ubuntu/anaconda3/envs/grand/lib/python3.7/site-packages/wandb/sdk/internal/internal_api.py", line 581, in sweep
    raise ValueError(f"Sweep {entity}/{project}/{sweep} not found")
ValueError: Sweep graph_neural_diffusion/hetero_tune_2hops/olbfb6ll not found

During handling of the above exception, another exception occurred:

Traceback (most recent call last):
  File "/home/ubuntu/anaconda3/envs/grand/lib/python3.7/site-packages/wandb/cli/cli.py", line 95, in wrapper
    return func(*args, **kwargs)
  File "/home/ubuntu/anaconda3/envs/grand/lib/python3.7/site-packages/wandb/cli/cli.py", line 1205, in agent
    wandb_agent.agent(sweep_id, entity=entity, project=project, count=count)
  File "/home/ubuntu/anaconda3/envs/grand/lib/python3.7/site-packages/wandb/wandb_agent.py", line 612, in agent
    count=count,
  File "/home/ubuntu/anaconda3/envs/grand/lib/python3.7/site-packages/wandb/wandb_agent.py", line 548, in run_agent
    agent.run()
  File "/home/ubuntu/anaconda3/envs/grand/lib/python3.7/site-packages/wandb/wandb_agent.py", line 181, in run
    sweep_obj = self._api.sweep(self._sweep_id, "{}")
  File "/home/ubuntu/anaconda3/envs/grand/lib/python3.7/site-packages/wandb/apis/internal.py", line 99, in sweep
    return self.api.sweep(*args, **kwargs)
  File "/home/ubuntu/anaconda3/envs/grand/lib/python3.7/site-packages/wandb/apis/normalize.py", line 58, in wrapper
    raise CommError(message, err).with_traceback(sys.exc_info()[2])
  File "/home/ubuntu/anaconda3/envs/grand/lib/python3.7/site-packages/wandb/apis/normalize.py", line 22, in wrapper
    return func(*args, **kwargs)
  File "/home/ubuntu/anaconda3/envs/grand/lib/python3.7/site-packages/wandb/sdk/internal/internal_api.py", line 581, in sweep
    raise ValueError(f"Sweep {entity}/{project}/{sweep} not found")
wandb.errors.CommError: Sweep graph_neural_diffusion/hetero_tune_2hops/olbfb6ll not found

2022-05-04 18:53:40 ERROR Traceback (most recent call last):
  File "/home/ubuntu/anaconda3/envs/grand/lib/python3.7/site-packages/wandb/apis/normalize.py", line 22, in wrapper
    return func(*args, **kwargs)
  File "/home/ubuntu/anaconda3/envs/grand/lib/python3.7/site-packages/wandb/sdk/internal/internal_api.py", line 581, in sweep
    raise ValueError(f"Sweep {entity}/{project}/{sweep} not found")
ValueError: Sweep graph_neural_diffusion/hetero_tune_2hops/olbfb6ll not found

During handling of the above exception, another exception occurred:

Traceback (most recent call last):
  File "/home/ubuntu/anaconda3/envs/grand/lib/python3.7/site-packages/wandb/cli/cli.py", line 95, in wrapper
    return func(*args, **kwargs)
  File "/home/ubuntu/anaconda3/envs/grand/lib/python3.7/site-packages/wandb/cli/cli.py", line 1205, in agent
    wandb_agent.agent(sweep_id, entity=entity, project=project, count=count)
  File "/home/ubuntu/anaconda3/envs/grand/lib/python3.7/site-packages/wandb/wandb_agent.py", line 612, in agent
    count=count,
  File "/home/ubuntu/anaconda3/envs/grand/lib/python3.7/site-packages/wandb/wandb_agent.py", line 548, in run_agent
    agent.run()
  File "/home/ubuntu/anaconda3/envs/grand/lib/python3.7/site-packages/wandb/wandb_agent.py", line 181, in run
    sweep_obj = self._api.sweep(self._sweep_id, "{}")
  File "/home/ubuntu/anaconda3/envs/grand/lib/python3.7/site-packages/wandb/apis/internal.py", line 99, in sweep
    return self.api.sweep(*args, **kwargs)
  File "/home/ubuntu/anaconda3/envs/grand/lib/python3.7/site-packages/wandb/apis/normalize.py", line 58, in wrapper
    raise CommError(message, err).with_traceback(sys.exc_info()[2])
  File "/home/ubuntu/anaconda3/envs/grand/lib/python3.7/site-packages/wandb/apis/normalize.py", line 22, in wrapper
    return func(*args, **kwargs)
  File "/home/ubuntu/anaconda3/envs/grand/lib/python3.7/site-packages/wandb/sdk/internal/internal_api.py", line 581, in sweep
    raise ValueError(f"Sweep {entity}/{project}/{sweep} not found")
wandb.errors.CommError: Sweep graph_neural_diffusion/hetero_tune_2hops/olbfb6ll not found

2022-05-04 18:53:40 ERROR Traceback (most recent call last):
  File "/home/ubuntu/anaconda3/envs/grand/lib/python3.7/site-packages/wandb/apis/normalize.py", line 22, in wrapper
    return func(*args, **kwargs)
  File "/home/ubuntu/anaconda3/envs/grand/lib/python3.7/site-packages/wandb/sdk/internal/internal_api.py", line 581, in sweep
    raise ValueError(f"Sweep {entity}/{project}/{sweep} not found")
ValueError: Sweep graph_neural_diffusion/hetero_tune_2hops/olbfb6ll not found

During handling of the above exception, another exception occurred:

Traceback (most recent call last):
  File "/home/ubuntu/anaconda3/envs/grand/lib/python3.7/site-packages/wandb/cli/cli.py", line 95, in wrapper
    return func(*args, **kwargs)
  File "/home/ubuntu/anaconda3/envs/grand/lib/python3.7/site-packages/wandb/cli/cli.py", line 1205, in agent
    wandb_agent.agent(sweep_id, entity=entity, project=project, count=count)
  File "/home/ubuntu/anaconda3/envs/grand/lib/python3.7/site-packages/wandb/wandb_agent.py", line 612, in agent
    count=count,
  File "/home/ubuntu/anaconda3/envs/grand/lib/python3.7/site-packages/wandb/wandb_agent.py", line 548, in run_agent
    agent.run()
  File "/home/ubuntu/anaconda3/envs/grand/lib/python3.7/site-packages/wandb/wandb_agent.py", line 181, in run
    sweep_obj = self._api.sweep(self._sweep_id, "{}")
  File "/home/ubuntu/anaconda3/envs/grand/lib/python3.7/site-packages/wandb/apis/internal.py", line 99, in sweep
    return self.api.sweep(*args, **kwargs)
  File "/home/ubuntu/anaconda3/envs/grand/lib/python3.7/site-packages/wandb/apis/normalize.py", line 58, in wrapper
    raise CommError(message, err).with_traceback(sys.exc_info()[2])
  File "/home/ubuntu/anaconda3/envs/grand/lib/python3.7/site-packages/wandb/apis/normalize.py", line 22, in wrapper
    return func(*args, **kwargs)
  File "/home/ubuntu/anaconda3/envs/grand/lib/python3.7/site-packages/wandb/sdk/internal/internal_api.py", line 581, in sweep
    raise ValueError(f"Sweep {entity}/{project}/{sweep} not found")
wandb.errors.CommError: Sweep graph_neural_diffusion/hetero_tune_2hops/olbfb6ll not found

2022-05-04 18:53:40 ERROR Traceback (most recent call last):
  File "/home/ubuntu/anaconda3/envs/grand/lib/python3.7/site-packages/wandb/apis/normalize.py", line 22, in wrapper
    return func(*args, **kwargs)
  File "/home/ubuntu/anaconda3/envs/grand/lib/python3.7/site-packages/wandb/sdk/internal/internal_api.py", line 581, in sweep
    raise ValueError(f"Sweep {entity}/{project}/{sweep} not found")
ValueError: Sweep graph_neural_diffusion/hetero_tune_2hops/olbfb6ll not found

During handling of the above exception, another exception occurred:

Traceback (most recent call last):
  File "/home/ubuntu/anaconda3/envs/grand/lib/python3.7/site-packages/wandb/cli/cli.py", line 95, in wrapper
    return func(*args, **kwargs)
  File "/home/ubuntu/anaconda3/envs/grand/lib/python3.7/site-packages/wandb/cli/cli.py", line 1205, in agent
    wandb_agent.agent(sweep_id, entity=entity, project=project, count=count)
  File "/home/ubuntu/anaconda3/envs/grand/lib/python3.7/site-packages/wandb/wandb_agent.py", line 612, in agent
    count=count,
  File "/home/ubuntu/anaconda3/envs/grand/lib/python3.7/site-packages/wandb/wandb_agent.py", line 548, in run_agent
    agent.run()
  File "/home/ubuntu/anaconda3/envs/grand/lib/python3.7/site-packages/wandb/wandb_agent.py", line 181, in run
    sweep_obj = self._api.sweep(self._sweep_id, "{}")
  File "/home/ubuntu/anaconda3/envs/grand/lib/python3.7/site-packages/wandb/apis/internal.py", line 99, in sweep
    return self.api.sweep(*args, **kwargs)
  File "/home/ubuntu/anaconda3/envs/grand/lib/python3.7/site-packages/wandb/apis/normalize.py", line 58, in wrapper
    raise CommError(message, err).with_traceback(sys.exc_info()[2])
  File "/home/ubuntu/anaconda3/envs/grand/lib/python3.7/site-packages/wandb/apis/normalize.py", line 22, in wrapper
    return func(*args, **kwargs)
  File "/home/ubuntu/anaconda3/envs/grand/lib/python3.7/site-packages/wandb/sdk/internal/internal_api.py", line 581, in sweep
    raise ValueError(f"Sweep {entity}/{project}/{sweep} not found")
wandb.errors.CommError: Sweep graph_neural_diffusion/hetero_tune_2hops/olbfb6ll not found

2022-05-04 18:53:40 ERROR Traceback (most recent call last):
  File "/home/ubuntu/anaconda3/envs/grand/lib/python3.7/site-packages/wandb/apis/normalize.py", line 22, in wrapper
    return func(*args, **kwargs)
  File "/home/ubuntu/anaconda3/envs/grand/lib/python3.7/site-packages/wandb/sdk/internal/internal_api.py", line 581, in sweep
    raise ValueError(f"Sweep {entity}/{project}/{sweep} not found")
ValueError: Sweep graph_neural_diffusion/hetero_tune_2hops/olbfb6ll not found

During handling of the above exception, another exception occurred:

Traceback (most recent call last):
  File "/home/ubuntu/anaconda3/envs/grand/lib/python3.7/site-packages/wandb/cli/cli.py", line 95, in wrapper
    return func(*args, **kwargs)
  File "/home/ubuntu/anaconda3/envs/grand/lib/python3.7/site-packages/wandb/cli/cli.py", line 1205, in agent
    wandb_agent.agent(sweep_id, entity=entity, project=project, count=count)
  File "/home/ubuntu/anaconda3/envs/grand/lib/python3.7/site-packages/wandb/wandb_agent.py", line 612, in agent
    count=count,
  File "/home/ubuntu/anaconda3/envs/grand/lib/python3.7/site-packages/wandb/wandb_agent.py", line 548, in run_agent
    agent.run()
  File "/home/ubuntu/anaconda3/envs/grand/lib/python3.7/site-packages/wandb/wandb_agent.py", line 181, in run
    sweep_obj = self._api.sweep(self._sweep_id, "{}")
  File "/home/ubuntu/anaconda3/envs/grand/lib/python3.7/site-packages/wandb/apis/internal.py", line 99, in sweep
    return self.api.sweep(*args, **kwargs)
  File "/home/ubuntu/anaconda3/envs/grand/lib/python3.7/site-packages/wandb/apis/normalize.py", line 58, in wrapper
    raise CommError(message, err).with_traceback(sys.exc_info()[2])
  File "/home/ubuntu/anaconda3/envs/grand/lib/python3.7/site-packages/wandb/apis/normalize.py", line 22, in wrapper
    return func(*args, **kwargs)
  File "/home/ubuntu/anaconda3/envs/grand/lib/python3.7/site-packages/wandb/sdk/internal/internal_api.py", line 581, in sweep
    raise ValueError(f"Sweep {entity}/{project}/{sweep} not found")
wandb.errors.CommError: Sweep graph_neural_diffusion/hetero_tune_2hops/olbfb6ll not found

